Workbook

Sheet Nomes
A1: Nomes | B1: Gastos em 2020 | C1: Gastos em 2021 | D1: Gastos em 2022 | E1: Gastos em 2023 | F1: Gastos em 2024 | G1: Gastos em 2025 | H1: Gastos em 2026 | I1: Total
A2: Douglas | B2: ='Ano 2020 - Café'!O44 -> 35896 | C2: ='Ano 2021 - Café'!O63 -> 55635.69 | D2: ='Ano 2022 - café'!O48 -> 57936.01 | E2: ='Ano 2023 - café'!P25 -> 65452.98 | F2: ='Ano 2024 - café'!P31 -> 40365 | G2: ='Ano 2025 - café'!P68 -> 92124.14 | H2: ='Ano 2026 - café'!P50 -> 50068.25 | I2: =SUM(B2:H2) -> 397478.07
A3: Cruz | B3: ='Ano 2020 - Café'!O42 -> 48797.89 | C3: ='Ano 2021 - Café'!O61 -> 52050.5 | D3: ='Ano 2022 - café'!O46 -> 48415.33 | E3: ='Ano 2023 - café'!P23 -> 63966.54 | F3: ='Ano 2024 - café'!P29 -> 97575.55 | G3: ='Ano 2025 - café'!P66 -> 119328.76 | H3: ='Ano 2026 - café'!P48 -> 19688.32 | I3: =SUM(B3:H3) -> 449822.89
A4: Totais | B4: =B2+B3 -> 84693.89 | C4: =C2+C3 -> 107686.19 | D4: =SUM(D2:D3) -> 106351.34 | E4: =SUM(E2:E3) -> 129419.52 | F4: =SUM(F2:F3) -> 137940.55 | G4: =SUM(G2:G3) -> 211452.9 | H4: =SUM(H2:H3) -> 69756.57 | I4: =SUM(I2:I3) -> 847300.96
I6: Saldo Douglas | J6: =I2-I3 -> -52344.82
I7: Saldo Cruz | J7: =I3-I2 -> 52344.82

Sheet VENDA CAFÉ
A1: Nomes | B1: 2024 | C1: 2025 | D1: 2026 | E1: 2027 | F1: 2028 | G1: Total
A2: Douglas | B2: =77700+46987.88+56879.83+64695.21 -> 246262.92 | D2: =40032.64 -> 40032.64 | G2: =B2+C2+D2 -> 286295.56
A3: Cruz | B3: =77700+46987.88+56879.83+64695.21 -> 246262.92 | D3: =40032.64+29644 -> 69676.64 | G3: =B3+C3+D3 -> 315939.56
A4: Totais | B4: =B2+B3 -> 492525.84 | C4: =C2+C3 -> 0 | D4: =SUM(D2:D3) -> 109709.28 | E4: =SUM(E2:E3) -> 0 | F4: =SUM(F2:F3) -> 0 | G4: =SUM(G2:G3) -> 602235.12

Sheet Ano 2020 - Café
A1: Despesas | B1: Quem pagou ? | C1: Janeiro | D1: Fevereiro | E1: Março | F1: Abril | G1: Maio | H1: Junho | I1: Julho | J1: Agosto | K1: Setembro | L1: Outubro | M1: Novembro | N1: Dezembro | O1: Acumulado do Ano
A2: Limpeza terra | B2: Douglas | C2: 15000 | O2: =SUM(C2:N2) -> 15000
A3: Limpeza terra | B3: Cruz | C3: 12000 | O3: 12000
A4: Esqueletagem de café | B4: Cruz | J4: 2624 | O4: =SUM(C4:N4) -> 2624
A5: Calcário | B5: Douglas | K5: 2130 | O5: =SUM(C5:N5) -> 2130
A6: Transporte Clacário | B6: Cruz | K6: 1100 | O6: =SUM(C6:N6) -> 1100
A7: Transporte Gesso | B7: Cruz | K7: 1980 | O7: =SUM(C7:N7) -> 1980
A8: Óleo Diesel | B8: Cruz | L8: 354 | O8: =SUM(C8:N8) -> 354
A9: Òleo Diesel | B9: Cruz | L9: 284 | O9: =SUM(C9:N9) -> 284
A10: Folear Map Purificado | B10: Cruz | L10: 135 | O10: =SUM(C10:N10) -> 135
A11: Yaravita Bortrac 10 Litros | B11: Cruz | L11: 343 | O11: =SUM(C11:N11) -> 343
A12: Yaravita Café 10 litros | B12: Cruz | L12: 590 | O12: =SUM(C12:N12) -> 590
A13: Azimut 05 litros | B13: Cruz | L13: 463 | O13: =SUM(C13:N13) -> 463
A14: Rimon 05 litros | B14: Cruz | L14: 581 | O14: =SUM(C14:N14) -> 581
A15: Esterco 70920 kg | B15: Cruz | L15: 6381 | O15: =SUM(C15:N15) -> 6381
A16: Transporte esterco (4 viagens ) | B16: Cruz | L16: 4400 | O16: =SUM(C16:N16) -> 4400
A17: Stimulat 20 litros | B17: Cruz | L17: 3880 | O17: =SUM(C17:N17) -> 3880
A18: Imida 15 litros | B18: Cruz | L18: 717.5 | O18: =SUM(C18:N18) -> 717.5
A19: Adubo (1 tonelada) ano de 2019 | B19: Cruz | L19: 1940 | O19: =SUM(C19:N19) -> 1940
... A21: Óleo Diesel | B21: Cruz | L21: 69 | O21: =SUM(C21:N21) -> 69
A22: Sv. Trator (Altair) | B22: Cruz | K22: 1200 | O22: =SUM(C22:N22) -> 1200
A23: Adubo supersimplies (planta/café) 7,5 toneladas | B23: Cruz | M23: 2545 | O23: =SUM(C23:N23) -> 2545
A24: Adubo supersimplies (planta/café) 7,5 toneladas | B24: Douglas | M24: 8000 | O24: =SUM(C24:N24) -> 8000
A25: Shadow (randape) | B25: Cruz | M25: 277.39 | O25: =SUM(C25:N25) -> 277.39
A26: Lona de plástico | B26: Cruz | M26: 137 | O26: =SUM(C26:N26) -> 137
A27: Adubo Ureia (café) | B27: Cruz | M27: 3572 | O27: =SUM(C27:N27) -> 3572
A28: Verdadeiro/multiboro (café) | B28: Cruz | M28: 1720 | O28: =SUM(C28:N28) -> 1720
A29: Palha de café | B29: Douglas | M29: 4000 | O29: =SUM(C29:N29) -> 4000
A30: Óleo Diesel | B30: Cruz | M30: 429 | O30: =SUM(C30:N30) -> 429
A31: Óleo Neen | B31: Cruz | J31: 450 | O31: =SUM(C31:N31) -> 450
A32: Óleo Diesel | B32: Cruz | N32: 465 | O32: =SUM(C32:N32) -> 465
A33: Mão de Obra | B33: Douglas | N33: 2640 | O33: =SUM(C33:N33) -> 2640
A34: Adubo Ureia 15 sacas | B34: Douglas | N34: 1410 | O34: =SUM(C34:N34) -> 1410
A35: Zartan, Galigan e Fert Fol Aminoagro | B35: Douglas | N35: 2160 | O35: =SUM(C35:N35) -> 2160
A36: Def. Cartago | B36: Douglas | N36: 235 | O36: =SUM(C36:N36) -> 235
A37: Óleo Diesel | B37: Douglas | N37: 173 | O37: =SUM(C37:N37) -> 173
A38: Salut 2 litros | B38: Douglas | N38: 148 | O38: =SUM(C38:N38) -> 148
A40: Total Despesas | C40: =SUM(C2:C39) -> 27000 | D40: =SUM(D2:D39) -> 0 | E40: =SUM(E2:E39) -> 0 | F40: =SUM(F2:F39) -> 0 | G40: =SUM(G2:G39) -> 0 | H40: =SUM(H2:H39) -> 0 | I40: =SUM(I2:I39) -> 0 | J40: =SUM(J2:J39) -> 3074 | ... O40: =SUM(O2:O39) -> 84693.89
A42: Total Pago | B42: José da Cruz | C42: =SUMIF($B1:$B38,"=Cruz",C1:C38) -> 12000 | D42: =SUMIF($B1:$B38,"=Cruz",D1:D38) -> 0 | E42: =SUMIF($B1:$B38,"=Cruz",E1:E38) -> 0 | F42: =SUMIF($B1:$B38,"=Cruz",F1:F38) -> 0 | G42: =SUMIF($B1:$B38,"=Cruz",G1:G38) -> 0 | H42: =SUMIF($B1:$B38,"=Cruz",H1:H38) -> 0 | I42: =SUMIF($B1:$B38,"=Cruz",I1:I38) -> 0 | J42: =SUMIF($B1:$B38,"=Cruz",J1:J38) -> 3074 | ... O42: =SUMIF($B1:$B38,"=Cruz",O1:O38) -> 48797.89
A44: Total Pago | B44: Douglas | C44: =SUMIF($B1:$B38,"=Douglas",C1:C38) -> 15000 | D44: =SUMIF($B1:$B38,"=Douglas",D1:D38) -> 0 | E44: =SUMIF($B1:$B38,"=Douglas",E1:E38) -> 0 | F44: =SUMIF($B1:$B38,"=Douglas",F1:F38) -> 0 | G44: =SUMIF($B1:$B38,"=Douglas",G1:G38) -> 0 | H44: =SUMIF($B1:$B38,"=Douglas",H1:H38) -> 0 | I44: =SUMIF($B1:$B38,"=Douglas",I1:I38) -> 0 | J44: =SUMIF($B1:$B38,"=Douglas",J1:J38) -> 0 | ... O44: =SUMIF($B1:$B38,"=Douglas",O1:O38) -> 35896
...

Sheet Ano 2021 - Café
A1: Despesas | B1: Quem pagou ? | C1: Janeiro | D1: Fevereiro | E1: Março | F1: Abril | G1: Maio | H1: Junho | I1: Julho | J1: Agosto | K1: Setembro | L1: Outubro | M1: Novembro | N1: Dezembro | O1: Acumulado do Ano
A2: Defensivo | B2: Cruz | C2: 142 | O2: =SUM(C2:N2) -> 142
A3: Adubo(Sulfato) | B3: Cruz | C3: 684 | O3: =SUM(C3:N3) -> 684
A4: Defensivo | B4: Douglas | C4: 503 | O4: =SUM(C4:N4) -> 503
A5: Defensivo | B5: Douglas | C5: 1145.69 | O5: =SUM(C5:N5) -> 1145.69
A6: Adudo pgto Cisley (40 sacas ureia protegida) | B6: Douglas | C6: 5200 | O6: =SUM(C6:N6) -> 5200
A7: Adubo Sulfato (2 adubação café novo) | B7: Douglas | C7: 546 | O7: =SUM(C7:N7) -> 546
A8: Adubo 20020 (3 adubação café velho) ** | B8: Douglas | C8: 3500 | O8: =SUM(C8:N8) -> 3500
A9: Adubo (Turfa e NPK) | B9: Douglas | C9: 2500 | O9: =SUM(C9:N9) -> 2500
A10: Defensivo | B10: Cruz | C10: 192.5 | O10: =SUM(C10:N10) -> 192.5
A11: Mudas de café | B11: Douglas | D11: 6900 | O11: =SUM(C11:N11) -> 6900
A12: Óleo diesel | B12: Cruz | D12: 1020 | O12: =SUM(C12:N12) -> 1020
A13: Serviço trator Marcinho | B13: Cruz | D13: 3800 | O13: =SUM(C13:N13) -> 3800
A14: Oléo doessel | B14: Cruz | D14: 772 | O14: =SUM(C14:N14) -> 772
A15: Defensivos** | B15: Cruz | D15: 230 | O15: =SUM(C15:N15) -> 230
A16: Defensivos** | B16: Douglas | E16: 1270 | O16: =SUM(C16:N16) -> 1270
A17: Oleo Diesel | B17: Douglas | E17: 552 | O17: =SUM(C17:N17) -> 552
A18: Defensivos | B18: Douglas | E18: 1744 | O18: =SUM(C18:N18) -> 1744
A19: Adubo 40 sacas (café velho e novo) | B19: Douglas | E19: 5200 | O19: =SUM(C19:N19) -> 5200
A20: Oleo diesel | B20: Cruz | F20: 475 | O20: =SUM(C20:N20) -> 475
A21: Defensivo sperto 2 litros | B21: Cruz | G21: 460 | O21: =SUM(C21:N21) -> 460
A22: Defensivo Cash (bicho mineiro) | B22: Cruz | G22: 480 | O22: =SUM(C22:N22) -> 480
A23: Óleo diesel | B23: Cruz | G23: 385 | O23: =SUM(C23:N23) -> 385
A24: MAp foliar | B24: Cruz | H24: 170 | O24: =SUM(C24:N24) -> 170
A25: Defensivo Acetamiprid 3 kg | B25: Cruz | H25: 345 | O25: =SUM(C25:N25) -> 345
A26: Defensivo Match 05 lt | B26: Cruz | H26: 290 | O26: =SUM(C26:N26) -> 290
A27: Óleo Diesel | B27: Cruz | H27: 87 | O27: =SUM(C27:N27) -> 87
A28: Esterco/carreto | B28: Cruz | H28: 2250 | O28: =SUM(C28:N28) -> 2250
A29: Defensivos (após colheita e bicho mineiro) | B29: Cruz | H29: 246 | O29: =SUM(C29:N29) -> 246
A30: Óleo Diesel | B30: Cruz | H30: 760 | O30: =SUM(C30:N30) -> 760
A31: Defensivo - envidor 3 frascos | B31: Cruz | I31: 900 | O31: =SUM(C31:N31) -> 900
A32: Espalhante l litro | B32: Cruz | I32: 60 | O32: =SUM(C32:N32) -> 60
A33: Esterco (trnp e comissão) Toninho | B33: Cruz | J33: =1800+450 -> 2250 | O33: =SUM(C33:N33) -> 2250
A34: Esterco (trnp e comissão) | B34: Cruz | J34: =4500+300+1500 -> 6300 | O34: =SUM(C34:N34) -> 6300
A35: Esterco/carreto Toninho | B35: Cruz | J35: =1700+500 -> 2200 | O35: =SUM(C35:N35) -> 2200
A36: Diárias (jogar café no chão) | B36: Cruz | J36: 240 | O36: =SUM(C36:N36) -> 240
A37: Adubo Eurin | B37: Douglas | L37: 3500 | O37: =SUM(C37:N37) -> 3500
A38: Adubo Eurin | B38: Cruz | L38: 3900 | O38: =SUM(C38:N38) -> 3900
A39: Defensivos - primeira aplicão | B39: Cruz | L39: 1600 | O39: =SUM(C39:N39) -> 1600
A40: Adubo 20.00.20 | B40: Douglas | M40: 1300 | O40: =SUM(C40:N40) -> 1300
...

Sheet Ano 2022 - café
A1: Despesas | B1: Quem pagou ? | C1: Janeiro | D1: Fevereiro | E1: Março | F1: Abril | G1: Maio | H1: Junho | I1: Julho | J1: Agosto | K1: Setembro | L1: Outubro | M1: Novembro | N1: Dezembro | O1: Acumulado do Ano
A2: Defensivos | B2: Cruz | C2: 210 | O2: =SUM(C2:N2) -> 210
A3: Oléo de Laranja (Terpen) | B3: Cruz | C3: 110 | O3: =SUM(C3:N3) -> 110
A4: Foliar Floema | B4: Cruz | C4: 235 | O4: =SUM(C4:N4) -> 235
A5: Adubo (30 sc ureia e 12 sc sulfato [parte]) | B5: Cruz | C5: 1105 | O5: =SUM(C5:N5) -> 1105
A6: Óleo vegetal e Prior xtra | B6: Cruz | C6: 595 | O6: =SUM(C6:N6) -> 595
A7: Actara, Magnésio, MAP e mineral | B7: Cruz | C7: 1770 | M7: 2810 | O7: =SUM(C7:N7) -> 4580
A8: Clorimuron | B8: Cruz | C8: 123.5 | O8: =SUM(C8:N8) -> 123.5
A9: Diárias (capina café velho) | B9: Cruz | C9: 350 | O9: =SUM(C9:N9) -> 350
A10: Adubos | B10: Douglas | C10: 10000 | M10: 17400 | O10: =SUM(C10:N10) -> 27400
A11: Defensivos | B11: Douglas | C11: 95 | L11: 2030 | O11: =SUM(C11:N11) -> 2125
A12: Acido boro | B12: Cruz | C12: 180 | O12: =SUM(C12:N12) -> 180
A13: Diárias (capina café velho) | B13: Cruz | D13: 180 | O13: =SUM(C13:N13) -> 180
A14: Streak e curyom | B14: Cruz | D14: 300 | O14: =SUM(C14:N14) -> 300
A15: Priori stra, sperto e streak | B15: Douglas | D15: 1695 | O15: =SUM(C15:N15) -> 1695
A16: Foliares Floema | B16: Douglas | D16: 828 | O16: =SUM(C16:N16) -> 828
A17: Adfix | B17: Douglas | E17: 600 | O17: =SUM(C17:N17) -> 600
A18: Fertilizantes (nitrato de Calcio) | B18: Cruz | E18: 450 | O18: =SUM(C18:N18) -> 450
A19: Fertilizantes (Boro, Magnesio e potassio) | B19: Douglas | E19: 970 | O19: =SUM(C19:N19) -> 970
A20: Priori extra, ampligo | B20: Douglas | E20: 1380 | O20: =SUM(C20:N20) -> 1380
A21: Zartan e Select | B21: Douglas | E21: 590 | O21: =SUM(C21:N21) -> 590
A22: Diárias | B22: Douglas | F22: 850 | M22: 570 | O22: =SUM(C22:N22) -> 1420
A23: Abamectin, Match e Nexide | B23: Cruz | F23: 1100 | O23: =SUM(C23:N23) -> 1100
A24: Alto 1000 (comprado da Cisley) | B24: Cruz | F24: 360 | O24: =SUM(C24:N24) -> 360
A25: defensivo, curyom (PARTE) | B25: Douglas | G25: 500 | O25: =SUM(C25:N25) -> 500
A26: Esterco/carreto | B26: Douglas | G26: 3000 | O26: =SUM(C26:N26) -> 3000
A27: Defensivos | B27: Cruz | G27: 107 | L27: 624 | O27: =SUM(C27:N27) -> 731
A28: Defensivo, vertimec | B28: Cruz | G28: 180 | L28: 180 | M28: 1000 | O28: =SUM(C28:N28) -> 1360
A29: Defensivos | B29: Cruz | G29: 730 | J29: 360 | O29: =SUM(C29:N29) -> 1090
A30: Esterco/carreto | B30: Cruz | H30: 6803 | N30: 150.00 | O30: 9803
A31: Esterco/carreto | B31: Douglas | H31: 6000 | O31: =SUM(C31:N31) -> 6000
A32: Serviço Altair (trator) | B32: Douglas | I32: 6460 | O32: =SUM(C32:N32) -> 6460
A33: serviço colheita (adiantado para Miguel) | B33: Cruz | I33: 1303 | O33: =SUM(C33:N33) -> 1303
A34: Diárias | B34: Cruz | H34: 300 | J34: 1100 | O34: =SUM(C34:N34) -> 1400
A35: óleo diessel para colheita | B35: Douglas | I35: 2058.21 | K35: 1212.8 | O35: =SUM(C35:N35) -> 3271.01
A36: Serviço colheita(adiantado para Miguel) | B36: Douglas | I36: 1697 | O36: =SUM(C36:N36) -> 1697
A37: Serviço Marcinho (pulverização) | B37: Cruz | K37: 303 | L37: 1375 | N37: 4200 | O37: =SUM(C37:N37) -> 5878
A38: Colheita (Natalino) | B38: Cruz | J38: 2125 | O38: =SUM(C38:N38) -> 2125
A39: Recolheidora (café chão) | B39: Cruz | J39: 3000 | O39: =SUM(C39:N39) -> 3000
A40: Sv. Altair | B40: Cruz | K40: 6955.83 | L40: 1961 | O40: =SUM(C40:N40) -> 8916.83
...

Sheet Ano 2023 - café
A1: Despesas | B1: Data NF | C1: Quem pagou ? | D1: Janeiro | E1: Fevereiro | F1: Março | G1: Abril | H1: Maio | I1: Junho | J1: Julho | K1: Agosto | L1: Setembro | M1: Outubro | N1: Novembro | O1: Dezembro | P1: Acumulado do Ano
A2: Armazenamento café até Janeiro 2023 | C2: Cruz | D2: 1372.85 | E2: 223 | F2: 274.6 | G2: 254.24 | I2: 272.4 | J2: 272.4 | K2: 465.19 | M2: 596.5 | N2: 573 | O2: 592.1 | P2: =SUM(D2:O2) -> 4896.28
A3: Diárias | C3: Cruz | D3: 1100 | P3: =SUM(D3:O3) -> 1100
A4: Diárias | C4: Douglas | D4: 2000 | P4: =SUM(D4:O4) -> 2000
A5: Defensivos | C5: Cruz | D5: 2590 | E5: 5912.4 | F5: 1336 | G5: 1010.32 | I5: 440 | J5: 760 | K5: 365 | L5: 630 | M5: 1730 | N5: 5843 | P5: =SUM(D5:O5) -> 20616.72
A6: Servico trator Altair (óleo) | C6: Cruz | D6: 1786.23 | F6: 711.18 | G6: 1000 | I6: 1861 | J6: 2375 | K6: 1740 | P6: =SUM(D6:O6) -> 9473.41
A7: Adubos | B7: 45278 | C7: Douglas | D7: 12000 | E7: 8000 | P7: =SUM(D7:N7) -> 20000
A8: Armazenamento Café | C8: Douglas | H8: 281.48 | P8: =SUM(D8:O8) -> 281.48
A9: Colheita (adiantado pro Miguel em óleo) | C9: Cruz | F9: 3022.13 | P9: =SUM(D9:O9) -> 3022.13
A10: Defensifos | C10: Douglas | G10: 5000 | H10: 2719 | P10: =SUM(D10:O10) -> 7719
A11: Colheita café novo | C11: Douglas | I11: 9000 | P11: =SUM(D11:O11) -> 9000
A12: Colheita café novo | C12: Cruz | I12: 3100 | P12: =SUM(D12:O12) -> 3100
A13: Serviço Marcinho (carreta café colhido) | C13: Cruz | I13: 455 | K13: 960 | P13: =SUM(D13:O13) -> 1415
A14: Esterco | C14: Douglas | J14: 9215 | P14: =SUM(D14:O14) -> 9215
A15: Esterco + carreto | C15: Cruz | J15: 4425 | P15: =SUM(D15:O15) -> 4425
A16: Análise de solo | C16: Cruz | I16: 498 | P16: =SUM(D16:O16) -> 498
A17: Sacas pra café | C17: Cruz | J17: 120 | P17: =SUM(D17:O17) -> 120
A18: Sv. Marcinho e Altair | C18: Douglas | O18: 17237.5 | P18: =SUM(D18:O18) -> 17237.5
A19: dubo | C19: Cruz | O19: 15300 | P19: =SUM(D19:O19) -> 15300
P20: =SUM(D20:O20) -> 0
A21: Total Despesas | D21: =SUM(D2:D20) -> 20849.08 | E21: =SUM(E2:E20) -> 14135.4 | F21: =SUM(F2:F20) -> 5343.91 | G21: =SUM(G2:G20) -> 7264.56 | H21: =SUM(H2:H20) -> 3000.48 | I21: =SUM(I2:I20) -> 15626.4 | J21: =SUM(J2:J20) -> 17167.4 | K21: =SUM(K2:K20) -> 3530.19 | ... P21: =SUM(P2:P20) -> 129419.52
A23: Total Pago | C23: José da Cruz | D23: =SUMIF($C1:$C19,"=Cruz",D1:D19) -> 6849.08 | E23: =SUMIF($C1:$C19,"=Cruz",E1:E19) -> 6135.4 | F23: =SUMIF($C1:$C19,"=Cruz",F1:F19) -> 5343.91 | G23: =SUMIF($C1:$C19,"=Cruz",G1:G19) -> 2264.56 | H23: =SUMIF($C1:$C19,"=Cruz",H1:H19) -> 0 | I23: =SUMIF($C1:$C19,"=Cruz",I1:I19) -> 6626.4 | J23: =SUMIF($C1:$C19,"=Cruz",J1:J19) -> 7952.4 | K23: =SUMIF($C1:$C19,"=Cruz",K1:K19) -> 3530.19 | ... P23: =SUMIF($C1:$C19,"=Cruz",P1:P19) -> 63966.54
A25: Total Pago | C25: Douglas | D25: =SUMIF($C1:$C19,"=Douglas",D1:D19) -> 14000 | E25: =SUMIF($C1:$C19,"=Douglas",E1:E19) -> 8000 | F25: =SUMIF($C1:$C19,"=Douglas",F1:F19) -> 0 | G25: =SUMIF($C1:$C19,"=Douglas",G1:G19) -> 5000 | H25: =SUMIF($C1:$C19,"=Douglas",H1:H19) -> 3000.48 | I25: =SUMIF($C1:$C19,"=Douglas",I1:I19) -> 9000 | J25: =SUMIF($C1:$C19,"=Douglas",J1:J19) -> 9215 | K25: =SUMIF($C1:$C19,"=Douglas",K1:K19) -> 0 | ... P25: =SUMIF($C1:$C19,"=Douglas",P1:P19) -> 65452.98

Sheet Ano 2024 - café
A1: Despesas | B1: NR NF | C1: Quem pagou ? | D1: Janeiro | E1: Fevereiro | F1: Março | G1: Abril | H1: Maio | I1: Junho | J1: Julho | K1: Agosto | L1: Setembro | M1: Outubro | N1: Novembro | O1: Dezembro | P1: Acumulado do Ano
A2: Defensivos | B2: 74071 | C2: Douglas | D2: 2105 | P2: =SUM(D2:O2) -> 2105
A3: Defensivos | B3: 000.072.154 | C3: Douglas | D3: 1640 | P3: =SUM(D3:O3) -> 1640
A4: Adubo | B4: 000.072.157 | C4: Douglas | D4: 5120 | P4: =SUM(D4:O4) -> 5120
A5: Colheita café novo | C5: Douglas | J5: 17050 | P5: =SUM(D5:O5) -> 17050
A6: Lanche - marmitex | C6: Douglas | J6: 450 | P6: =SUM(D6:N6) -> 450
A7: Lanche - marmiitex | C7: Cruz | J7: 200 | P7: =SUM(D7:O7) -> 200
A8: Colheita café velho | C8: Cruz | J8: 6400 | P8: =SUM(D8:O8) -> 6400
A9: sv trincha - Dalton | C9: Cruz | I9: 910 | P9: =SUM(D9:O9) -> 910
A10: Diária bateção café | C10: Douglas | J10: 1200 | P10: =SUM(D10:O10) -> 1200
A11: oléo diessel colheitadeira | C11: Cruz | J11: 1390 | P11: =SUM(D11:O11) -> 1390
A12: Defensivo | C12: Cruz | E12: 9577 | G12: 4075 | J12: 1440 | N12: 4005 | O12: 11230 | P12: =SUM(D12:O12) -> 30327
A13: sacas | C13: Cruz | J13: 418 | P13: =SUM(D13:O13) -> 418
A14: Armazenamento | C14: Cruz | D14: 592.1 | E14: 783.6 | L14: 327.75 | M14: 312.9 | P14: =SUM(D14:O14) -> 2016.35
A15: Servicos trator Altair | C15: Cruz | J15: 21627 | M15: 4880 | P15: =SUM(D15:O15) -> 26507
A16: Calcário - gesso | C16: Cruz | L16: 5950 | P16: =SUM(D16:O16) -> 5950
A17: Carreto Calcário e geeso | C17: Douglas | L17: 2800 | P17: =SUM(D17:O17) -> 2800
A18: Análise de solo | C18: Cruz | K18: 187.2 | P18: =SUM(D18:O18) -> 187.2
A19: Colheita café chão | C19: Cruz | K19: 5000 | P19: =SUM(D19:O19) -> 5000
A20: Sv Altair (calcario e gesso) | C20: Cruz | M20: 2235 | P20: =SUM(D20:O20) -> 2235
A21: Sv Altair (adubação, pulverização e randup) | C21: Cruz | N21: 2795 | O21: 4800 | P21: =SUM(D21:O21) -> 7595
A22: Adubo 5 toneladas (ureia e supr simples) parte | C22: Douglas | N22: 10000 | P22: =SUM(D22:O22) -> 10000
A23: Adubo (ureia e supr simples) parte e carreto | C23: Cruz | N23: 5250 | P23: =SUM(D23:O23) -> 5250
A24: 500 Kg de uréia compado do Altair | C24: Cruz | O24: 1750 | P24: =SUM(D24:O24) -> 1750
A25: Diarias desbrotamento | C25: Cruz | O25: 1440 | P25: =SUM(D25:O25) -> 1440
P26: =SUM(D26:O26) -> 0
A27: Total Despesas | D27: =SUM(D2:D26) -> 9457.1 | E27: =SUM(E2:E26) -> 10360.6 | F27: =SUM(F2:F26) -> 0 | G27: =SUM(G2:G26) -> 4075 | H27: =SUM(H2:H26) -> 0 | I27: =SUM(I2:I26) -> 910 | J27: =SUM(J2:J26) -> 50175 | K27: =SUM(K2:K26) -> 5187.2 | ... P27: =SUM(P2:P26) -> 137940.55
A29: Total Pago | C29: José da Cruz | D29: =SUMIF($C1:$C24,"=Cruz",D1:D24) -> 592.1 | E29: =SUMIF($C1:$C24,"=Cruz",E1:E24) -> 10360.6 | F29: =SUMIF($C1:$C24,"=Cruz",F1:F24) -> 0 | G29: =SUMIF($C1:$C24,"=Cruz",G1:G24) -> 4075 | H29: =SUMIF($C1:$C24,"=Cruz",H1:H24) -> 0 | I29: =SUMIF($C1:$C24,"=Cruz",I1:I24) -> 910 | J29: =SUMIF($C1:$C24,"=Cruz",J1:J24) -> 31475 | K29: =SUMIF($C1:$C24,"=Cruz",K1:K24) -> 5187.2 | ... O29: =SUMIF($C1:$C24,"=Cruz",O1:O24) -> 17780 | P29: =SUMIF($C1:$C26,"=Cruz",P1:P26) -> 97575.55
A31: Total Pago | C31: Douglas | D31: =SUMIF($C1:$C24,"=Douglas",D1:D24) -> 8865 | E31: =SUMIF($C1:$C24,"=Douglas",E1:E24) -> 0 | F31: =SUMIF($C1:$C24,"=Douglas",F1:F24) -> 0 | G31: =SUMIF($C1:$C24,"=Douglas",G1:G24) -> 0 | H31: =SUMIF($C1:$C24,"=Douglas",H1:H24) -> 0 | I31: =SUMIF($C1:$C24,"=Douglas",I1:I24) -> 0 | J31: =SUMIF($C1:$C24,"=Douglas",J1:J24) -> 18700 | K31: =SUMIF($C1:$C24,"=Douglas",K1:K24) -> 0 | ... O31: =SUMIF($C1:$C24,"=Douglas",O1:O24) -> 0 | P31: =SUMIF($C1:$C26,"=Douglas",P1:P26) -> 40365

Sheet Ano 2025 - café
A1: Despesas | B1: NR NF | C1: Quem pagou ? | D1: Janeiro | E1: Fevereiro | F1: Março | G1: Abril | H1: Maio | I1: Junho | J1: Julho | K1: Agosto | L1: Setembro | M1: Outubro | N1: Novembro | O1: Dezembro | P1: Acumulado do Ano
A2: Defensivo | C2: Cruz | D2: 5179 | F2: 875 | P2: =SUM(D2:O2) -> 6054
A3: Sv Altair | C3: Cruz | D3: 3258 | E3: 1232 | P3: =SUM(D3:O3) -> 4490
A4: Diarias - amarrração galhos de café | C4: Cruz | F4: 260 | P4: =SUM(D4:O4) -> 260
A5: Sv Altair pulverização | C5: Cruz | F5: 1026 | P5: =SUM(D5:O5) -> 1026
A6: Sv Altair trincha | C6: Cruz | G6: 2730 | P6: =SUM(D6:O6) -> 2730
A7: Sv Altair randup | C7: Cruz | H7: 840 | P7: =SUM(D7:O7) -> 840
A8: Sv Altair pulverizaçÕ | C8: Cruz | H8: 770 | P8: =SUM(D8:O8) -> 770
A9: Devensivo | C9: Cruz | F9: 925 | P9: =SUM(D9:O9) -> 925
A10: Adubo | C10: Douglas | F10: 5890 | P10: =SUM(D10:O10) -> 5890
A11: Defensivo | C11: Cruz | F11: 395 | P11: =SUM(D11:O11) -> 395
A12: defensivo | C12: Cruz | H12: 3060 | P12: =SUM(D12:O12) -> 3060
A13: Colheita café novo | C13: Douglas | K13: 7800 | P13: =SUM(D13:O13) -> 7800
A14: Pulverizaçao e carretos | C14: Cruz | K14: 1530 | P14: =SUM(D14:O14) -> 1530
A15: Colheita café velho | C15: Douglas | L15: 4000 | P15: =SUM(D15:O15) -> 4000
A16: Oleo maquinas colheita | C16: Douglas | L16: 2000 | P16: =SUM(D16:O16) -> 2000
A17: defensivo | C17: Douglas | J17: 1065 | K17: 1300 | P17: =SUM(D17:O17) -> 2365
A18: Sv Altair | C18: Douglas | F18: 1764 | P18: =SUM(D18:O18) -> 1764
A19: Sv Altair: varreção,colheita chão e óleo diesel | C19: Cruz | J19: 10210 | M19: 265 | P19: =SUM(D19:O19) -> 10475
A20: Diárias - jogar café no chão | C20: Cruz | J20: 1200 | P20: =SUM(D20:O20) -> 1200
A21: vitim - gradeação roma | C21: Cruz | M21: 2074 | P21: =SUM(D21:O21) -> 2074
A22: compra esterco | C22: Cruz | M22: 18811 | P22: =SUM(D22:O22) -> 18811
A23: calcario | C23: Cruz | M23: 2212 | P23: =SUM(D23:O23) -> 2212
A24: Carreto gesso e calcário | C24: Cruz | M24: 1950 | P24: =SUM(D24:O24) -> 1950
A25: gradeação niveladora | C25: Cruz | M25: 1075 | P25: =SUM(D25:O25) -> 1075
A26: Limpez e rancar tocos | C26: Cruz | M26: 10500 | P26: =SUM(D26:O26) -> 10500
A27: Sv altair - esterco, calcário e gesso | C27: Cruz | M27: 5680 | P27: =SUM(D27:O27) -> 5680
A28: Sv Marcinho - encher minami, suco, dubo e tampar sucos | C28: Cruz | M28: 5680 | P28: =SUM(D28:O28) -> 5680
A29: carretos - mudas e adubo | C29: Cruz | N29: 8353 | P29: =SUM(D29:O29) -> 8353
A30: Diárias-plantação de café | C30: Cruz | N30: 11800 | P30: =SUM(D30:O30) -> 11800
A31: Sv trincha café novo Eder | C31: Cruz | M31: 1100 | P31: =SUM(D31:O31) -> 1100
A32: Diárias amarração de glhos de café e frete | C32: Cruz | N32: 1100 | P32: =SUM(D32:O32) -> 1100
A33: Sv sebastião - encher minami | C33: Cruz | M33: 200 | P33: =SUM(D33:O33) -> 200
A34: cordão | C34: Cruz | N34: 1000 | P34: =SUM(D34:O34) -> 1000
A35: diarias capina e frete | C35: Cruz | N35: 1500 | P35: =SUM(D35:O35) -> 1500
A36: Sv Altair trincha café velho de cima | C36: Cruz | N36: 1260 | P36: =SUM(D36:O36) -> 1260
A37: diárias cordda de viola | C37: Cruz | N37: 850 | P37: =SUM(D37:O37) -> 850
A38: diárias replante e adubação | C38: Cruz | O38: 1300 | P38: =SUM(D38:O38) -> 1300
A39: mudas viveiro proximo CAMIG | C39: Douglas | O39: 960 | P39: =SUM(D39:O39) -> 960
A40: Mudas viveiro São João | C40: Cruz | O40: 3000 | P40: =SUM(D40:O40) -> 3000
...

Sheet Ano 2026 - café
A1: Despesas | B1: NR NF | C1: Quem pagou ? | D1: Janeiro | E1: Fevereiro | F1: Março | G1: Abril | H1: Maio | I1: Junho | J1: Julho | K1: Agosto | L1: Setembro | M1: Outubro | N1: Novembro | O1: Dezembro | P1: Acumulado do Ano
A2: Defensivos | C2: Douglas | D2: 1620 | P2: =SUM(F2:O2) -> 0
A3: adubo | C3: Douglas | D3: 1050 | P3: =SUM(F3:O3) -> 0
A4: defensivos | C4: Douglas | D4: 1490 | P4: =SUM(F4:O4) -> 0
A5: Adubo | C5: Douglas | D5: 10200
A6: Armazenamento | C6: Douglas | D6: 261.64
A7: Defensivos | C7: Douglas | D7: 2250
A8: Defenaivo | C8: Douglas | D8: 100
A9: Defensivos | C9: Douglas | D9: 175
A10: Adubo e defensivo | C10: Douglas | D10: 480
A11: Defensivos | C11: Douglas | D11: 825
A12: armazenamento | C12: Douglas | E12: 261.61
A13: defensivos | C13: Douglas | E13: 870
A14: defensivos | C14: Douglas | E14: 530
A15: Defensivos | C15: Douglas | E15: 300
A16: Mudas ( NF tirada em Fev -plantadas Nov 2025 | C16: Douglas | E16: 17550
A17: sv altair | C17: Douglas | E17: 9000 | P17: =SUM(D17:O17) -> 9000
A18: Diárias - amarração café e capina + fretes | C18: Douglas | E18: 3105 | P18: =SUM(D18:O18) -> 3105
A19: Diárias - amarração café e capina + fretes | C19: Cruz | E19: 7585
A20: adubo | C20: Cruz | E20: 1100
A21: Melaço | C21: Cruz | E21: 140
A22: defensivos | C22: Cruz | E22: 955
A23: sv Marcinho (defensivo via voliar e solo | C23: Cruz | F23: 900
A24: defensivo pego com Edson | C24: Cruz | F24: 1277
A25: armazenamento | C25: Cruz | F25: 236.32
A26: defensivo | C26: cruz | F26: 2600 | P26: =SUM(D26:O26) -> 2600
A27: defensivo | C27: Cruz | F27: 2886 | P27: =SUM(D27:O27) -> 2886
A28: herbicida | C28: Cruz | F28: 900 | P28: =SUM(D28:O28) -> 900
A29: glisofato | C29: Cruz | F29: 789 | P29: =SUM(D29:O29) -> 789
A30: Clorimurom | C30: Cruz | F30: 320 | P30: =SUM(D30:O30) -> 320
P31: =SUM(D31:O31) -> 0
P32: =SUM(D32:O32) -> 0
P33: =SUM(D33:O33) -> 0
P34: =SUM(D34:O34) -> 0
P35: =SUM(D35:O35) -> 0
P36: =SUM(D36:O36) -> 0
P37: =SUM(D37:O37) -> 0
P38: =SUM(D38:O38) -> 0
P39: =SUM(D39:O39) -> 0
P40: =SUM(D40:O40) -> 0
...
